Traceback (most recent call last):
  File "/home/sullberg/repos/pypospack/pypospack/potential/eamembed_eos_rose.py", line 275, in evaluate
    xtol=a_tol)
  File "/home/sullberg/anaconda3/lib/python3.6/site-packages/scipy/optimize/zeros.py", line 519, in brentq
    r = _zeros._brentq(f,a,b,xtol,rtol,maxiter,args,full_output,disp)
ValueError: f(a) and f(b) must have different signs

During handling of the above exception, another exception occurred:

Traceback (most recent call last):
  File "/home/sullberg/repos/pypospack/pypospack/pyposmat/engines/mc_sampler.py", line 315, in run_parameteric_sampling
    _results = self.evaluate_parameter_set(parameters=_parameters)
  File "/home/sullberg/repos/pypospack/pypospack/pyposmat/engines/engine.py", line 212, in evaluate_parameter_set
    setfl_fn=setfl_fn
  File "/home/sullberg/repos/pypospack/pypospack/pyposmat/engines/engine.py", line 180, in write_eam_setfl_file
    parameters=parameters
  File "/home/sullberg/repos/pypospack/pypospack/potential/eam.py", line 203, in write_setfl_file
    parameters=parameters)
  File "/home/sullberg/repos/pypospack/pypospack/potential/eam.py", line 230, in evaluate
    self.evaluate_embedding(rho)
  File "/home/sullberg/repos/pypospack/pypospack/potential/eam.py", line 407, in evaluate_embedding
    o_density=self.obj_density)
  File "/home/sullberg/repos/pypospack/pypospack/potential/eamembed_eos_rose.py", line 278, in evaluate
    raise PypospackBadEamEosError
pypospack.exceptions.PypospackBadEamEosError

During handling of the above exception, another exception occurred:

Traceback (most recent call last):
  File "mc_iterative_sampler.py", line 19, in <module>
    pyposmat_app.run_all()
  File "/home/sullberg/repos/pypospack/pypospack/pyposmat/engines/mc_sampler_iterate.py", line 205, in run_all
    self.run_simulations(i)
  File "/home/sullberg/repos/pypospack/pypospack/pyposmat/engines/mc_sampler_iterate.py", line 407, in run_simulations
    self.run_parametric_sampling(i_iteration=i_iteration)
  File "/home/sullberg/repos/pypospack/pypospack/pyposmat/engines/mc_sampler_iterate.py", line 561, in run_parametric_sampling
    n_samples=self.determine_number_of_samples_per_rank(i_iteration=i_iteration))
  File "/home/sullberg/repos/pypospack/pypospack/pyposmat/engines/mc_sampler.py", line 195, in run_simulations
    self.run_parameteric_sampling(n_samples=_n_samples)
  File "/home/sullberg/repos/pypospack/pypospack/pyposmat/engines/mc_sampler.py", line 326, in run_parameteric_sampling
    self.pyposmat_badparameters.write_simulation_exception(sim_id=sim_id,exception=e)
  File "/home/sullberg/repos/pypospack/pypospack/pyposmat/data/badparametersfile.py", line 126, in write_simulation_exception
    + [s_reason]
  File "/home/sullberg/repos/pypospack/pypospack/pyposmat/data/badparametersfile.py", line 125, in <listcomp>
    + [str(exception.kwargs['parameters'][k]) for k in self.parameter_names] \
KeyError: 'parameters'
Traceback (most recent call last):
  File "/home/sullberg/repos/pypospack/pypospack/potential/eamembed_eos_rose.py", line 275, in evaluate
    xtol=a_tol)
  File "/home/sullberg/anaconda3/lib/python3.6/site-packages/scipy/optimize/zeros.py", line 519, in brentq
    r = _zeros._brentq(f,a,b,xtol,rtol,maxiter,args,full_output,disp)
ValueError: f(a) and f(b) must have different signs

During handling of the above exception, another exception occurred:

Traceback (most recent call last):
  File "/home/sullberg/repos/pypospack/pypospack/pyposmat/engines/mc_sampler.py", line 315, in run_parameteric_sampling
    _results = self.evaluate_parameter_set(parameters=_parameters)
  File "/home/sullberg/repos/pypospack/pypospack/pyposmat/engines/engine.py", line 212, in evaluate_parameter_set
    setfl_fn=setfl_fn
  File "/home/sullberg/repos/pypospack/pypospack/pyposmat/engines/engine.py", line 180, in write_eam_setfl_file
    parameters=parameters
  File "/home/sullberg/repos/pypospack/pypospack/potential/eam.py", line 203, in write_setfl_file
    parameters=parameters)
  File "/home/sullberg/repos/pypospack/pypospack/potential/eam.py", line 230, in evaluate
    self.evaluate_embedding(rho)
  File "/home/sullberg/repos/pypospack/pypospack/potential/eam.py", line 407, in evaluate_embedding
    o_density=self.obj_density)
  File "/home/sullberg/repos/pypospack/pypospack/potential/eamembed_eos_rose.py", line 278, in evaluate
    raise PypospackBadEamEosError
pypospack.exceptions.PypospackBadEamEosError

During handling of the above exception, another exception occurred:

Traceback (most recent call last):
  File "mc_iterative_sampler.py", line 19, in <module>
    pyposmat_app.run_all()
  File "/home/sullberg/repos/pypospack/pypospack/pyposmat/engines/mc_sampler_iterate.py", line 205, in run_all
    self.run_simulations(i)
  File "/home/sullberg/repos/pypospack/pypospack/pyposmat/engines/mc_sampler_iterate.py", line 407, in run_simulations
    self.run_parametric_sampling(i_iteration=i_iteration)
  File "/home/sullberg/repos/pypospack/pypospack/pyposmat/engines/mc_sampler_iterate.py", line 561, in run_parametric_sampling
    n_samples=self.determine_number_of_samples_per_rank(i_iteration=i_iteration))
  File "/home/sullberg/repos/pypospack/pypospack/pyposmat/engines/mc_sampler.py", line 195, in run_simulations
    self.run_parameteric_sampling(n_samples=_n_samples)
  File "/home/sullberg/repos/pypospack/pypospack/pyposmat/engines/mc_sampler.py", line 326, in run_parameteric_sampling
    self.pyposmat_badparameters.write_simulation_exception(sim_id=sim_id,exception=e)
  File "/home/sullberg/repos/pypospack/pypospack/pyposmat/data/badparametersfile.py", line 126, in write_simulation_exception
    + [s_reason]
  File "/home/sullberg/repos/pypospack/pypospack/pyposmat/data/badparametersfile.py", line 125, in <listcomp>
    + [str(exception.kwargs['parameters'][k]) for k in self.parameter_names] \
KeyError: 'parameters'
Traceback (most recent call last):
  File "/home/sullberg/repos/pypospack/pypospack/potential/eamembed_eos_rose.py", line 275, in evaluate
    xtol=a_tol)
  File "/home/sullberg/anaconda3/lib/python3.6/site-packages/scipy/optimize/zeros.py", line 519, in brentq
    r = _zeros._brentq(f,a,b,xtol,rtol,maxiter,args,full_output,disp)
ValueError: f(a) and f(b) must have different signs

During handling of the above exception, another exception occurred:

Traceback (most recent call last):
  File "/home/sullberg/repos/pypospack/pypospack/pyposmat/engines/mc_sampler.py", line 315, in run_parameteric_sampling
    _results = self.evaluate_parameter_set(parameters=_parameters)
  File "/home/sullberg/repos/pypospack/pypospack/pyposmat/engines/engine.py", line 212, in evaluate_parameter_set
    setfl_fn=setfl_fn
  File "/home/sullberg/repos/pypospack/pypospack/pyposmat/engines/engine.py", line 180, in write_eam_setfl_file
    parameters=parameters
  File "/home/sullberg/repos/pypospack/pypospack/potential/eam.py", line 203, in write_setfl_file
    parameters=parameters)
  File "/home/sullberg/repos/pypospack/pypospack/potential/eam.py", line 230, in evaluate
    self.evaluate_embedding(rho)
  File "/home/sullberg/repos/pypospack/pypospack/potential/eam.py", line 407, in evaluate_embedding
    o_density=self.obj_density)
  File "/home/sullberg/repos/pypospack/pypospack/potential/eamembed_eos_rose.py", line 278, in evaluate
    raise PypospackBadEamEosError
pypospack.exceptions.PypospackBadEamEosError

During handling of the above exception, another exception occurred:

Traceback (most recent call last):
  File "mc_iterative_sampler.py", line 19, in <module>
    pyposmat_app.run_all()
  File "/home/sullberg/repos/pypospack/pypospack/pyposmat/engines/mc_sampler_iterate.py", line 205, in run_all
    self.run_simulations(i)
  File "/home/sullberg/repos/pypospack/pypospack/pyposmat/engines/mc_sampler_iterate.py", line 407, in run_simulations
    self.run_parametric_sampling(i_iteration=i_iteration)
  File "/home/sullberg/repos/pypospack/pypospack/pyposmat/engines/mc_sampler_iterate.py", line 561, in run_parametric_sampling
    n_samples=self.determine_number_of_samples_per_rank(i_iteration=i_iteration))
  File "/home/sullberg/repos/pypospack/pypospack/pyposmat/engines/mc_sampler.py", line 195, in run_simulations
    self.run_parameteric_sampling(n_samples=_n_samples)
  File "/home/sullberg/repos/pypospack/pypospack/pyposmat/engines/mc_sampler.py", line 326, in run_parameteric_sampling
    self.pyposmat_badparameters.write_simulation_exception(sim_id=sim_id,exception=e)
  File "/home/sullberg/repos/pypospack/pypospack/pyposmat/data/badparametersfile.py", line 126, in write_simulation_exception
    + [s_reason]
  File "/home/sullberg/repos/pypospack/pypospack/pyposmat/data/badparametersfile.py", line 125, in <listcomp>
    + [str(exception.kwargs['parameters'][k]) for k in self.parameter_names] \
KeyError: 'parameters'
